running with Ivan deep learning work
SLURM job ID: 121012
dataset: ../../data/project2024/
预训练模型已经存在，无需下载。
预训练模型已经存在，无需下载。
missing_keys:  ['classifier.4.weight', 'classifier.4.bias']
unexpected_keys:  ['aux_classifier.0.weight', 'aux_classifier.1.weight', 'aux_classifier.1.bias', 'aux_classifier.1.running_mean', 'aux_classifier.1.running_var', 'aux_classifier.1.num_batches_tracked']
Task name: deeplab  num_workers: 4
Using device: cuda
Using version: 2.2.1

Device name: Tesla P100-PCIE-16GB
Total memory: 15.8992919921875 GB
Allocated memory: 0.0 GB
Cached memory: 0.0 GB
optimizer name: sgd
loss name:  ce
Epoch 1/100
----------
  0%|          | 0/34 [00:00<?, ?it/s]  3%|▎         | 1/34 [00:28<15:48, 28.76s/it] 12%|█▏        | 4/34 [00:33<03:25,  6.85s/it] 12%|█▏        | 4/34 [00:50<03:25,  6.85s/it] 18%|█▊        | 6/34 [01:03<04:45, 10.21s/it] 26%|██▋       | 9/34 [01:08<02:32,  6.12s/it] 35%|███▌      | 12/34 [01:17<01:46,  4.82s/it] 44%|████▍     | 15/34 [01:25<01:17,  4.08s/it] 53%|█████▎    | 18/34 [01:36<01:02,  3.90s/it] 59%|█████▉    | 20/34 [01:47<01:01,  4.37s/it] 68%|██████▊   | 23/34 [02:02<00:49,  4.52s/it] 74%|███████▎  | 25/34 [02:09<00:39,  4.34s/it] 79%|███████▉  | 27/34 [02:15<00:27,  3.96s/it] 85%|████████▌ | 29/34 [02:24<00:20,  4.15s/it] 85%|████████▌ | 29/34 [02:24<00:24,  5.00s/it]
Traceback (most recent call last):
  File "/home/Student/s4715365/testfolder/comp7840/deep_learning/segmentation/seg.py", line 433, in <module>
    train_model(model, device, 
    ^^^^^^^^^^^^^^^^^^^^^^^^^^
  File "/home/Student/s4715365/testfolder/comp7840/deep_learning/segmentation/seg.py", line 211, in train_model
    for i, data in enumerate(tqdm(dataloader, mininterval=5)):
  File "/home/Student/s4715365/anaconda3/envs/venv/lib/python3.11/site-packages/tqdm/std.py", line 1181, in __iter__
    for obj in iterable:
  File "/home/Student/s4715365/anaconda3/envs/venv/lib/python3.11/site-packages/torch/utils/data/dataloader.py", line 631, in __next__
    data = self._next_data()
           ^^^^^^^^^^^^^^^^^
  File "/home/Student/s4715365/anaconda3/envs/venv/lib/python3.11/site-packages/torch/utils/data/dataloader.py", line 1326, in _next_data
    return self._process_data(data)
           ^^^^^^^^^^^^^^^^^^^^^^^^
  File "/home/Student/s4715365/anaconda3/envs/venv/lib/python3.11/site-packages/torch/utils/data/dataloader.py", line 1372, in _process_data
    data.reraise()
  File "/home/Student/s4715365/anaconda3/envs/venv/lib/python3.11/site-packages/torch/_utils.py", line 722, in reraise
    raise exception
ValueError: Caught ValueError in DataLoader worker process 1.
Original Traceback (most recent call last):
  File "/home/Student/s4715365/anaconda3/envs/venv/lib/python3.11/site-packages/torch/utils/data/_utils/worker.py", line 308, in _worker_loop
    data = fetcher.fetch(index)
           ^^^^^^^^^^^^^^^^^^^^
  File "/home/Student/s4715365/anaconda3/envs/venv/lib/python3.11/site-packages/torch/utils/data/_utils/fetch.py", line 51, in fetch
    data = [self.dataset[idx] for idx in possibly_batched_index]
           ^^^^^^^^^^^^^^^^^^^^^^^^^^^^^^^^^^^^^^^^^^^^^^^^^^^^^
  File "/home/Student/s4715365/anaconda3/envs/venv/lib/python3.11/site-packages/torch/utils/data/_utils/fetch.py", line 51, in <listcomp>
    data = [self.dataset[idx] for idx in possibly_batched_index]
            ~~~~~~~~~~~~^^^^^
  File "/home/Student/s4715365/testfolder/comp7840/deep_learning/segmentation/seg.py", line 93, in __getitem__
    mask_np_array, _ = image_color_mapping(np.array(mask), self.color_map, file_name)
                       ^^^^^^^^^^^^^^^^^^^^^^^^^^^^^^^^^^^^^^^^^^^^^^^^^^^^^^^^^^^^^^
  File "/home/Student/s4715365/testfolder/comp7840/deep_learning/segmentation/../../other/image_handle.py", line 121, in image_color_mapping
    raise ValueError("image_color_mapping 中不应该生成新的颜色")
ValueError: image_color_mapping 中不应该生成新的颜色

srun: error: c4130-2: task 0: Exited with exit code 1
任务失败或异常结束
